<sdf version='1.7'>
  <world name='default'>
    <plugin name='welcome_message' filename='libwelcome_message.so'/>
    <light name='sun' type='directional'>
      <cast_shadows>1</cast_shadows>
      <pose>0 0 10 0 -0 0</pose>
      <diffuse>0.8 0.8 0.8 1</diffuse>
      <specular>0.2 0.2 0.2 1</specular>
      <attenuation>
        <range>1000</range>
        <constant>0.9</constant>
        <linear>0.01</linear>
        <quadratic>0.001</quadratic>
      </attenuation>
      <direction>-0.5 0.1 -0.9</direction>
      <spot>
        <inner_angle>0</inner_angle>
        <outer_angle>0</outer_angle>
        <falloff>0</falloff>
      </spot>
    </light>
    <model name='ground_plane'>
      <static>1</static>
      <link name='link'>
        <collision name='collision'>
          <geometry>
            <plane>
              <normal>0 0 1</normal>
              <size>100 100</size>
            </plane>
          </geometry>
          <surface>
            <contact>
              <collide_bitmask>65535</collide_bitmask>
              <ode/>
            </contact>
            <friction>
              <ode>
                <mu>100</mu>
                <mu2>50</mu2>
              </ode>
              <torsional>
                <ode/>
              </torsional>
            </friction>
            <bounce/>
          </surface>
          <max_contacts>10</max_contacts>
        </collision>
        <visual name='visual'>
          <cast_shadows>0</cast_shadows>
          <geometry>
            <plane>
              <normal>0 0 1</normal>
              <size>100 100</size>
            </plane>
          </geometry>
          <material>
            <script>
              <uri>file://media/materials/scripts/gazebo.material</uri>
              <name>Gazebo/Grey</name>
            </script>
          </material>
        </visual>
        <self_collide>0</self_collide>
        <enable_wind>0</enable_wind>
        <kinematic>0</kinematic>
      </link>
    </model>
    <gravity>0 0 -9.8</gravity>
    <magnetic_field>6e-06 2.3e-05 -4.2e-05</magnetic_field>
    <atmosphere type='adiabatic'/>
    <physics type='ode'>
      <max_step_size>0.001</max_step_size>
      <real_time_factor>1</real_time_factor>
      <real_time_update_rate>1000</real_time_update_rate>
    </physics>
    <scene>
      <ambient>0.4 0.4 0.4 1</ambient>
      <background>0.7 0.7 0.7 1</background>
      <shadows>1</shadows>
    </scene>
    <audio>
      <device>default</device>
    </audio>
    <wind/>
    <spherical_coordinates>
      <surface_model>EARTH_WGS84</surface_model>
      <latitude_deg>0</latitude_deg>
      <longitude_deg>0</longitude_deg>
      <elevation>0</elevation>
      <heading_deg>0</heading_deg>
    </spherical_coordinates>
    <model name='BrickBuilding'>
      <pose>-0.814927 -2.2475 0 0 -0 0</pose>
      <link name='Wall_0'>
        <collision name='Wall_0_Collision'>
          <geometry>
            <box>
              <size>1.75 0.15 2.5</size>
            </box>
          </geometry>
          <pose>0 0 1.25 0 -0 0</pose>
          <max_contacts>10</max_contacts>
          <surface>
            <contact>
              <ode/>
            </contact>
            <bounce/>
            <friction>
              <torsional>
                <ode/>
              </torsional>
              <ode/>
            </friction>
          </surface>
        </collision>
        <visual name='Wall_0_Visual'>
          <pose>0 0 1.25 0 -0 0</pose>
          <geometry>
            <box>
              <size>1.75 0.15 2.5</size>
            </box>
          </geometry>
          <material>
            <script>
              <uri>file://media/materials/scripts/gazebo.material</uri>
              <name>Gazebo/Bricks</name>
            </script>
            <ambient>1 1 1 1</ambient>
          </material>
          <meta>
            <layer>0</layer>
          </meta>
        </visual>
        <pose>-2.62507 -1.0725 0 0 -0 3.14159</pose>
        <self_collide>0</self_collide>
        <enable_wind>0</enable_wind>
        <kinematic>0</kinematic>
      </link>
      <link name='Wall_1'>
        <pose>-3.42507 -1.6225 0 0 -0 -1.5708</pose>
        <visual name='Wall_1_Visual_0'>
          <pose>-0.5325 0 1.25 0 -0 0</pose>
          <geometry>
            <box>
              <size>0.185 0.15 2.5</size>
            </box>
          </geometry>
          <material>
            <script>
              <uri>file://media/materials/scripts/gazebo.material</uri>
              <name>Gazebo/Bricks</name>
            </script>
            <ambient>1 1 1 1</ambient>
          </material>
          <meta>
            <layer>0</layer>
          </meta>
        </visual>
        <collision name='Wall_1_Collision_0'>
          <geometry>
            <box>
              <size>0.185 0.15 2.5</size>
            </box>
          </geometry>
          <pose>-0.5325 0 1.25 0 -0 0</pose>
          <max_contacts>10</max_contacts>
          <surface>
            <contact>
              <ode/>
            </contact>
            <bounce/>
            <friction>
              <torsional>
                <ode/>
              </torsional>
              <ode/>
            </friction>
          </surface>
        </collision>
        <visual name='Wall_1_Visual_1'>
          <pose>0.5425 0 1.25 0 -0 0</pose>
          <geometry>
            <box>
              <size>0.165 0.15 2.5</size>
            </box>
          </geometry>
          <material>
            <script>
              <uri>file://media/materials/scripts/gazebo.material</uri>
              <name>Gazebo/Bricks</name>
            </script>
            <ambient>1 1 1 1</ambient>
          </material>
          <meta>
            <layer>0</layer>
          </meta>
        </visual>
        <collision name='Wall_1_Collision_1'>
          <geometry>
            <box>
              <size>0.165 0.15 2.5</size>
            </box>
          </geometry>
          <pose>0.5425 0 1.25 0 -0 0</pose>
          <max_contacts>10</max_contacts>
          <surface>
            <contact>
              <ode/>
            </contact>
            <bounce/>
            <friction>
              <torsional>
                <ode/>
              </torsional>
              <ode/>
            </friction>
          </surface>
        </collision>
        <visual name='Wall_1_Visual_2'>
          <pose>0.01 0 2.25 0 -0 0</pose>
          <geometry>
            <box>
              <size>0.9 0.15 0.5</size>
            </box>
          </geometry>
          <material>
            <script>
              <uri>file://media/materials/scripts/gazebo.material</uri>
              <name>Gazebo/Bricks</name>
            </script>
            <ambient>1 1 1 1</ambient>
          </material>
          <meta>
            <layer>0</layer>
          </meta>
        </visual>
        <collision name='Wall_1_Collision_2'>
          <geometry>
            <box>
              <size>0.9 0.15 0.5</size>
            </box>
          </geometry>
          <pose>0.01 0 2.25 0 -0 0</pose>
          <max_contacts>10</max_contacts>
          <surface>
            <contact>
              <ode/>
            </contact>
            <bounce/>
            <friction>
              <torsional>
                <ode/>
              </torsional>
              <ode/>
            </friction>
          </surface>
        </collision>
        <self_collide>0</self_collide>
        <enable_wind>0</enable_wind>
        <kinematic>0</kinematic>
      </link>
      <link name='Wall_2'>
        <pose>-7.3e-05 -2.1725 0 0 -0 0</pose>
        <visual name='Wall_2_Visual_0'>
          <pose>-2.2775 0 1.25 0 -0 0</pose>
          <geometry>
            <box>
              <size>2.445 0.15 2.5</size>
            </box>
          </geometry>
          <material>
            <script>
              <uri>file://media/materials/scripts/gazebo.material</uri>
              <name>Gazebo/Bricks</name>
            </script>
            <ambient>1 1 1 1</ambient>
          </material>
          <meta>
            <layer>0</layer>
          </meta>
        </visual>
        <collision name='Wall_2_Collision_0'>
          <geometry>
            <box>
              <size>2.445 0.15 2.5</size>
            </box>
          </geometry>
          <pose>-2.2775 0 1.25 0 -0 0</pose>
          <max_contacts>10</max_contacts>
          <surface>
            <contact>
              <ode/>
            </contact>
            <bounce/>
            <friction>
              <torsional>
                <ode/>
              </torsional>
              <ode/>
            </friction>
          </surface>
        </collision>
        <visual name='Wall_2_Visual_1'>
          <pose>1.2225 0 0.25 0 -0 0</pose>
          <geometry>
            <box>
              <size>4.555 0.15 0.5</size>
            </box>
          </geometry>
          <material>
            <script>
              <uri>file://media/materials/scripts/gazebo.material</uri>
              <name>Gazebo/Bricks</name>
            </script>
            <ambient>1 1 1 1</ambient>
          </material>
          <meta>
            <layer>0</layer>
          </meta>
        </visual>
        <collision name='Wall_2_Collision_1'>
          <geometry>
            <box>
              <size>4.555 0.15 0.5</size>
            </box>
          </geometry>
          <pose>1.2225 0 0.25 0 -0 0</pose>
          <max_contacts>10</max_contacts>
          <surface>
            <contact>
              <ode/>
            </contact>
            <bounce/>
            <friction>
              <torsional>
                <ode/>
              </torsional>
              <ode/>
            </friction>
          </surface>
        </collision>
        <visual name='Wall_2_Visual_2'>
          <pose>0.22 0 1.5 0 -0 0</pose>
          <geometry>
            <box>
              <size>0.95 0.15 2</size>
            </box>
          </geometry>
          <material>
            <script>
              <uri>file://media/materials/scripts/gazebo.material</uri>
              <name>Gazebo/Bricks</name>
            </script>
            <ambient>1 1 1 1</ambient>
          </material>
          <meta>
            <layer>0</layer>
          </meta>
        </visual>
        <collision name='Wall_2_Collision_2'>
          <geometry>
            <box>
              <size>0.95 0.15 2</size>
            </box>
          </geometry>
          <pose>0.22 0 1.5 0 -0 0</pose>
          <max_contacts>10</max_contacts>
          <surface>
            <contact>
              <ode/>
            </contact>
            <bounce/>
            <friction>
              <torsional>
                <ode/>
              </torsional>
              <ode/>
            </friction>
          </surface>
        </collision>
        <visual name='Wall_2_Visual_3'>
          <pose>1.835 0 1.5 0 -0 0</pose>
          <geometry>
            <box>
              <size>0.68 0.15 2</size>
            </box>
          </geometry>
          <material>
            <script>
              <uri>file://media/materials/scripts/gazebo.material</uri>
              <name>Gazebo/Bricks</name>
            </script>
            <ambient>1 1 1 1</ambient>
          </material>
          <meta>
            <layer>0</layer>
          </meta>
        </visual>
        <collision name='Wall_2_Collision_3'>
          <geometry>
            <box>
              <size>0.68 0.15 2</size>
            </box>
          </geometry>
          <pose>1.835 0 1.5 0 -0 0</pose>
          <max_contacts>10</max_contacts>
          <surface>
            <contact>
              <ode/>
            </contact>
            <bounce/>
            <friction>
              <torsional>
                <ode/>
              </torsional>
              <ode/>
            </friction>
          </surface>
        </collision>
        <visual name='Wall_2_Visual_4'>
          <pose>3.2375 0 1.5 0 -0 0</pose>
          <geometry>
            <box>
              <size>0.525 0.15 2</size>
            </box>
          </geometry>
          <material>
            <script>
              <uri>file://media/materials/scripts/gazebo.material</uri>
              <name>Gazebo/Bricks</name>
            </script>
            <ambient>1 1 1 1</ambient>
          </material>
          <meta>
            <layer>0</layer>
          </meta>
        </visual>
        <collision name='Wall_2_Collision_4'>
          <geometry>
            <box>
              <size>0.525 0.15 2</size>
            </box>
          </geometry>
          <pose>3.2375 0 1.5 0 -0 0</pose>
          <max_contacts>10</max_contacts>
          <surface>
            <contact>
              <ode/>
            </contact>
            <bounce/>
            <friction>
              <torsional>
                <ode/>
              </torsional>
              <ode/>
            </friction>
          </surface>
        </collision>
        <visual name='Wall_2_Visual_5'>
          <pose>-0.655 0 1.9 0 -0 0</pose>
          <geometry>
            <box>
              <size>0.8 0.15 1.2</size>
            </box>
          </geometry>
          <material>
            <script>
              <uri>file://media/materials/scripts/gazebo.material</uri>
              <name>Gazebo/Bricks</name>
            </script>
            <ambient>1 1 1 1</ambient>
          </material>
          <meta>
            <layer>0</layer>
          </meta>
        </visual>
        <collision name='Wall_2_Collision_5'>
          <geometry>
            <box>
              <size>0.8 0.15 1.2</size>
            </box>
          </geometry>
          <pose>-0.655 0 1.9 0 -0 0</pose>
          <max_contacts>10</max_contacts>
          <surface>
            <contact>
              <ode/>
            </contact>
            <bounce/>
            <friction>
              <torsional>
                <ode/>
              </torsional>
              <ode/>
            </friction>
          </surface>
        </collision>
        <visual name='Wall_2_Visual_6'>
          <pose>1.095 0 1.9 0 -0 0</pose>
          <geometry>
            <box>
              <size>0.8 0.15 1.2</size>
            </box>
          </geometry>
          <material>
            <script>
              <uri>file://media/materials/scripts/gazebo.material</uri>
              <name>Gazebo/Bricks</name>
            </script>
            <ambient>1 1 1 1</ambient>
          </material>
          <meta>
            <layer>0</layer>
          </meta>
        </visual>
        <collision name='Wall_2_Collision_6'>
          <geometry>
            <box>
              <size>0.8 0.15 1.2</size>
            </box>
          </geometry>
          <pose>1.095 0 1.9 0 -0 0</pose>
          <max_contacts>10</max_contacts>
          <surface>
            <contact>
              <ode/>
            </contact>
            <bounce/>
            <friction>
              <torsional>
                <ode/>
              </torsional>
              <ode/>
            </friction>
          </surface>
        </collision>
        <visual name='Wall_2_Visual_7'>
          <pose>2.575 0 1.9 0 -0 0</pose>
          <geometry>
            <box>
              <size>0.8 0.15 1.2</size>
            </box>
          </geometry>
          <material>
            <script>
              <uri>file://media/materials/scripts/gazebo.material</uri>
              <name>Gazebo/Bricks</name>
            </script>
            <ambient>1 1 1 1</ambient>
          </material>
          <meta>
            <layer>0</layer>
          </meta>
        </visual>
        <collision name='Wall_2_Collision_7'>
          <geometry>
            <box>
              <size>0.8 0.15 1.2</size>
            </box>
          </geometry>
          <pose>2.575 0 1.9 0 -0 0</pose>
          <max_contacts>10</max_contacts>
          <surface>
            <contact>
              <ode/>
            </contact>
            <bounce/>
            <friction>
              <torsional>
                <ode/>
              </torsional>
              <ode/>
            </friction>
          </surface>
        </collision>
        <self_collide>0</self_collide>
        <enable_wind>0</enable_wind>
        <kinematic>0</kinematic>
      </link>
      <link name='Wall_3'>
        <collision name='Wall_3_Collision'>
          <geometry>
            <box>
              <size>4 0.15 2.5</size>
            </box>
          </geometry>
          <pose>0 0 1.25 0 -0 0</pose>
          <max_contacts>10</max_contacts>
          <surface>
            <contact>
              <ode/>
            </contact>
            <bounce/>
            <friction>
              <torsional>
                <ode/>
              </torsional>
              <ode/>
            </friction>
          </surface>
        </collision>
        <visual name='Wall_3_Visual'>
          <pose>0 0 1.25 0 -0 0</pose>
          <geometry>
            <box>
              <size>4 0.15 2.5</size>
            </box>
          </geometry>
          <material>
            <script>
              <uri>file://media/materials/scripts/gazebo.material</uri>
              <name>Gazebo/Bricks</name>
            </script>
            <ambient>1 1 1 1</ambient>
          </material>
          <meta>
            <layer>0</layer>
          </meta>
        </visual>
        <pose>3.42493 -0.2475 0 0 -0 1.5708</pose>
        <self_collide>0</self_collide>
        <enable_wind>0</enable_wind>
        <kinematic>0</kinematic>
      </link>
      <link name='Wall_4'>
        <pose>0.929927 1.6825 0 0 -0 3.13959</pose>
        <visual name='Wall_4_Visual_0'>
          <pose>-2.24747 0 1.25 0 -0 0</pose>
          <geometry>
            <box>
              <size>0.645053 0.15 2.5</size>
            </box>
          </geometry>
          <material>
            <script>
              <uri>file://media/materials/scripts/gazebo.material</uri>
              <name>Gazebo/Bricks</name>
            </script>
            <ambient>1 1 1 1</ambient>
          </material>
          <meta>
            <layer>0</layer>
          </meta>
        </visual>
        <collision name='Wall_4_Collision_0'>
          <geometry>
            <box>
              <size>0.645053 0.15 2.5</size>
            </box>
          </geometry>
          <pose>-2.24747 0 1.25 0 -0 0</pose>
          <max_contacts>10</max_contacts>
          <surface>
            <contact>
              <ode/>
            </contact>
            <bounce/>
            <friction>
              <torsional>
                <ode/>
              </torsional>
              <ode/>
            </friction>
          </surface>
        </collision>
        <visual name='Wall_4_Visual_1'>
          <pose>0.322527 0 0.25 0 -0 0</pose>
          <geometry>
            <box>
              <size>4.49495 0.15 0.5</size>
            </box>
          </geometry>
          <material>
            <script>
              <uri>file://media/materials/scripts/gazebo.material</uri>
              <name>Gazebo/Bricks</name>
            </script>
            <ambient>1 1 1 1</ambient>
          </material>
          <meta>
            <layer>0</layer>
          </meta>
        </visual>
        <collision name='Wall_4_Collision_1'>
          <geometry>
            <box>
              <size>4.49495 0.15 0.5</size>
            </box>
          </geometry>
          <pose>0.322527 0 0.25 0 -0 0</pose>
          <max_contacts>10</max_contacts>
          <surface>
            <contact>
              <ode/>
            </contact>
            <bounce/>
            <friction>
              <torsional>
                <ode/>
              </torsional>
              <ode/>
            </friction>
          </surface>
        </collision>
        <visual name='Wall_4_Visual_2'>
          <pose>-0.819918 0 1.5 0 -0 0</pose>
          <geometry>
            <box>
              <size>0.610057 0.15 2</size>
            </box>
          </geometry>
          <material>
            <script>
              <uri>file://media/materials/scripts/gazebo.material</uri>
              <name>Gazebo/Bricks</name>
            </script>
            <ambient>1 1 1 1</ambient>
          </material>
          <meta>
            <layer>0</layer>
          </meta>
        </visual>
        <collision name='Wall_4_Collision_2'>
          <geometry>
            <box>
              <size>0.610057 0.15 2</size>
            </box>
          </geometry>
          <pose>-0.819918 0 1.5 0 -0 0</pose>
          <max_contacts>10</max_contacts>
          <surface>
            <contact>
              <ode/>
            </contact>
            <bounce/>
            <friction>
              <torsional>
                <ode/>
              </torsional>
              <ode/>
            </friction>
          </surface>
        </collision>
        <visual name='Wall_4_Visual_3'>
          <pose>0.725089 0 1.5 0 -0 0</pose>
          <geometry>
            <box>
              <size>0.879957 0.15 2</size>
            </box>
          </geometry>
          <material>
            <script>
              <uri>file://media/materials/scripts/gazebo.material</uri>
              <name>Gazebo/Bricks</name>
            </script>
            <ambient>1 1 1 1</ambient>
          </material>
          <meta>
            <layer>0</layer>
          </meta>
        </visual>
        <collision name='Wall_4_Collision_3'>
          <geometry>
            <box>
              <size>0.879957 0.15 2</size>
            </box>
          </geometry>
          <pose>0.725089 0 1.5 0 -0 0</pose>
          <max_contacts>10</max_contacts>
          <surface>
            <contact>
              <ode/>
            </contact>
            <bounce/>
            <friction>
              <torsional>
                <ode/>
              </torsional>
              <ode/>
            </friction>
          </surface>
        </collision>
        <visual name='Wall_4_Visual_4'>
          <pose>2.26753 0 1.5 0 -0 0</pose>
          <geometry>
            <box>
              <size>0.604933 0.15 2</size>
            </box>
          </geometry>
          <material>
            <script>
              <uri>file://media/materials/scripts/gazebo.material</uri>
              <name>Gazebo/Bricks</name>
            </script>
            <ambient>1 1 1 1</ambient>
          </material>
          <meta>
            <layer>0</layer>
          </meta>
        </visual>
        <collision name='Wall_4_Collision_4'>
          <geometry>
            <box>
              <size>0.604933 0.15 2</size>
            </box>
          </geometry>
          <pose>2.26753 0 1.5 0 -0 0</pose>
          <max_contacts>10</max_contacts>
          <surface>
            <contact>
              <ode/>
            </contact>
            <bounce/>
            <friction>
              <torsional>
                <ode/>
              </torsional>
              <ode/>
            </friction>
          </surface>
        </collision>
        <visual name='Wall_4_Visual_5'>
          <pose>-1.52495 0 1.9 0 -0 0</pose>
          <geometry>
            <box>
              <size>0.8 0.15 1.2</size>
            </box>
          </geometry>
          <material>
            <script>
              <uri>file://media/materials/scripts/gazebo.material</uri>
              <name>Gazebo/Bricks</name>
            </script>
            <ambient>1 1 1 1</ambient>
          </material>
          <meta>
            <layer>0</layer>
          </meta>
        </visual>
        <collision name='Wall_4_Collision_5'>
          <geometry>
            <box>
              <size>0.8 0.15 1.2</size>
            </box>
          </geometry>
          <pose>-1.52495 0 1.9 0 -0 0</pose>
          <max_contacts>10</max_contacts>
          <surface>
            <contact>
              <ode/>
            </contact>
            <bounce/>
            <friction>
              <torsional>
                <ode/>
              </torsional>
              <ode/>
            </friction>
          </surface>
        </collision>
        <visual name='Wall_4_Visual_6'>
          <pose>-0.11489 0 1.9 0 -0 0</pose>
          <geometry>
            <box>
              <size>0.8 0.15 1.2</size>
            </box>
          </geometry>
          <material>
            <script>
              <uri>file://media/materials/scripts/gazebo.material</uri>
              <name>Gazebo/Bricks</name>
            </script>
            <ambient>1 1 1 1</ambient>
          </material>
          <meta>
            <layer>0</layer>
          </meta>
        </visual>
        <collision name='Wall_4_Collision_6'>
          <geometry>
            <box>
              <size>0.8 0.15 1.2</size>
            </box>
          </geometry>
          <pose>-0.11489 0 1.9 0 -0 0</pose>
          <max_contacts>10</max_contacts>
          <surface>
            <contact>
              <ode/>
            </contact>
            <bounce/>
            <friction>
              <torsional>
                <ode/>
              </torsional>
              <ode/>
            </friction>
          </surface>
        </collision>
        <visual name='Wall_4_Visual_7'>
          <pose>1.56507 0 1.9 0 -0 0</pose>
          <geometry>
            <box>
              <size>0.8 0.15 1.2</size>
            </box>
          </geometry>
          <material>
            <script>
              <uri>file://media/materials/scripts/gazebo.material</uri>
              <name>Gazebo/Bricks</name>
            </script>
            <ambient>1 1 1 1</ambient>
          </material>
          <meta>
            <layer>0</layer>
          </meta>
        </visual>
        <collision name='Wall_4_Collision_7'>
          <geometry>
            <box>
              <size>0.8 0.15 1.2</size>
            </box>
          </geometry>
          <pose>1.56507 0 1.9 0 -0 0</pose>
          <max_contacts>10</max_contacts>
          <surface>
            <contact>
              <ode/>
            </contact>
            <bounce/>
            <friction>
              <torsional>
                <ode/>
              </torsional>
              <ode/>
            </friction>
          </surface>
        </collision>
        <self_collide>0</self_collide>
        <enable_wind>0</enable_wind>
        <kinematic>0</kinematic>
      </link>
      <link name='Wall_7'>
        <collision name='Wall_7_Collision'>
          <geometry>
            <box>
              <size>2.92222 0.15 2.5</size>
            </box>
          </geometry>
          <pose>0 0 1.25 0 -0 0</pose>
          <max_contacts>10</max_contacts>
          <surface>
            <contact>
              <ode/>
            </contact>
            <bounce/>
            <friction>
              <torsional>
                <ode/>
              </torsional>
              <ode/>
            </friction>
          </surface>
        </collision>
        <visual name='Wall_7_Visual'>
          <pose>0 0 1.25 0 -0 0</pose>
          <geometry>
            <box>
              <size>2.92222 0.15 2.5</size>
            </box>
          </geometry>
          <material>
            <script>
              <uri>file://media/materials/scripts/gazebo.material</uri>
              <name>Gazebo/Bricks</name>
            </script>
            <ambient>1 1 1 1</ambient>
          </material>
          <meta>
            <layer>0</layer>
          </meta>
        </visual>
        <pose>-1.69507 0.3075 0 0 -0 -1.66472</pose>
        <self_collide>0</self_collide>
        <enable_wind>0</enable_wind>
        <kinematic>0</kinematic>
      </link>
      <static>1</static>
    </model>
    <state world_name='default'>
      <sim_time>826 878000000</sim_time>
      <real_time>232 628666439</real_time>
      <wall_time>1607208827 345420520</wall_time>
      <iterations>228910</iterations>
      <model name='BrickBuilding'>
        <pose>-0.81493 -2.2475 0 0 -0 0</pose>
        <scale>1 1 1</scale>
        <link name='Wall_0'>
          <pose>-3.44 -3.32 0 0 -0 3.14159</pose>
          <velocity>0 0 0 0 -0 0</velocity>
          <acceleration>nan nan nan nan nan nan</acceleration>
          <wrench>0 0 0 0 -0 0</wrench>
        </link>
        <link name='Wall_1'>
          <pose>-4.24 -3.87 0 0 0 -1.5708</pose>
          <velocity>0 0 0 0 -0 0</velocity>
          <acceleration>nan nan nan nan nan nan</acceleration>
          <wrench>0 0 0 0 -0 0</wrench>
        </link>
        <link name='Wall_2'>
          <pose>-0.815 -4.42 0 0 -0 0</pose>
          <velocity>0 0 0 0 -0 0</velocity>
          <acceleration>nan nan nan nan nan nan</acceleration>
          <wrench>0 0 0 0 -0 0</wrench>
        </link>
        <link name='Wall_3'>
          <pose>2.61 -2.495 0 0 -0 1.5708</pose>
          <velocity>0 0 0 0 -0 0</velocity>
          <acceleration>nan nan nan nan nan nan</acceleration>
          <wrench>0 0 0 0 -0 0</wrench>
        </link>
        <link name='Wall_4'>
          <pose>0.115 -0.565 0 0 -0 3.13959</pose>
          <velocity>0 0 0 0 -0 0</velocity>
          <acceleration>nan nan nan nan nan nan</acceleration>
          <wrench>0 0 0 0 -0 0</wrench>
        </link>
        <link name='Wall_7'>
          <pose>-2.51 -1.94 0 0 0 -1.66472</pose>
          <velocity>0 0 0 0 -0 0</velocity>
          <acceleration>nan nan nan nan nan nan</acceleration>
          <wrench>0 0 0 0 -0 0</wrench>
        </link>
      </model>
      <model name='ambulance'>
        <pose>-7.8224 -4.0409 0 0 -0 0</pose>
        <scale>1 1 1</scale>
        <link name='link'>
          <pose>-7.8224 -4.0409 0 0 -0 0</pose>
          <velocity>0 0 0 0 -0 0</velocity>
          <acceleration>nan nan nan nan nan nan</acceleration>
          <wrench>0 0 0 0 -0 0</wrench>
        </link>
      </model>
      <model name='cessna_c172'>
        <pose>7.67751 3.85957 0.492439 0.000312 -0.000612 -0.012169</pose>
        <scale>1 1 1</scale>
        <link name='body'>
          <pose>7.67751 3.85957 0.492439 0.000312 -0.000612 -0.012169</pose>
          <velocity>-0.003702 -0.000999 -0.001448 0.004862 0.003314 0.002174</velocity>
          <acceleration>0.008455 0.172966 -5.33904 0.076371 1.43216 -0.018144</acceleration>
          <wrench>5.75281 117.684 -3632.62 0 -0 0</wrench>
        </link>
        <link name='elevators'>
          <pose>7.20249 3.86445 3.37608 0.000362 -0.530616 -0.012352</pose>
          <velocity>0.009409 -0.016094 -0.007744 0.004881 0.004849 0.002175</velocity>
          <acceleration>-0.628571 0.315695 2.67917 0.096074 1.32258 -0.017738</acceleration>
          <wrench>-1.25714 0.63139 5.35834 0 -0 0</wrench>
        </link>
        <link name='front_wheel'>
          <pose>7.66751 3.85975 0.468691 0.000187 -0.033867 -0.012177</pose>
          <velocity>-0.009442 -0.012697 -0.041551 0.036127 -0.016361 0.002651</velocity>
          <acceleration>-1.76504 -5.04727 -33.998 1.13921 -1.12224 0.132748</acceleration>
          <wrench>-3.53008 -10.0945 -67.996 0 -0 0</wrench>
        </link>
        <link name='left_aileron'>
          <pose>8.07643 3.74896 1.6245 -0.061704 -0.526651 -0.022762</pose>
          <velocity>0.004494 -0.009091 0.05406 0.001595 -0.021269 0.000924</velocity>
          <acceleration>3.36787 0.04341 -6.88829 2.47646 -0.399804 -1.40377</acceleration>
          <wrench>6.73573 0.086819 -13.7766 0 -0 0</wrench>
        </link>
        <link name='left_flap'>
          <pose>8.16421 3.83332 1.49329 0.00355 -0.530496 -0.024073</pose>
          <velocity>-0.000924 -0.004736 -0.006246 0.004881 0.004819 0.002205</velocity>
          <acceleration>0.672138 0.171065 -2.7542 0.084197 0.833784 -0.029262</acceleration>
          <wrench>1.34428 0.34213 -5.50841 0 -0 0</wrench>
        </link>
        <link name='propeller'>
          <pose>9.46685 3.83753 1.34853 0.013005 -0.000612 -0.012169</pose>
          <velocity>-0.000818 -0.001217 -0.007494 0.000238 0.003346 0.002226</velocity>
          <acceleration>-0.095114 0.27445 -7.48135 0.01839 1.42617 -1.84197</acceleration>
          <wrench>-1.74724 5.04165 -137.432 0 -0 0</wrench>
        </link>
        <link name='rear_left_wheel'>
          <pose>7.65223 3.86011 0.585792 -0.000388 -0.086816 -0.012137</pose>
          <velocity>-0.011303 -0.001626 0.023218 0.006104 -0.024752 0.002356</velocity>
          <acceleration>0.007158 0.233946 0.074437 -0.934932 -0.035659 0.220991</acceleration>
          <wrench>0.014315 0.467892 0.148875 0 -0 0</wrench>
        </link>
        <link name='rear_right_wheel'>
          <pose>7.59444 3.85971 0.723375 0.002096 -0.229774 -0.012644</pose>
          <velocity>-0.004464 -0.003424 0.01609 0.007149 -0.00291 0.002004</velocity>
          <acceleration>-0.124277 0.167233 -0.020822 -0.647285 -0.380191 -0.347783</acceleration>
          <wrench>-0.248554 0.334467 -0.041644 0 -0 0</wrench>
        </link>
        <link name='right_aileron'>
          <pose>8.079 3.95974 1.62458 0.062427 -0.526662 -0.001938</pose>
          <velocity>-0.001662 -0.006779 -0.021849 0.003939 0.011847 0.001747</velocity>
          <acceleration>-3.92834 0.063368 4.3354 -1.27747 -1.24828 0.791753</acceleration>
          <wrench>-7.85668 0.126736 8.67079 0 -0 0</wrench>
        </link>
        <link name='right_flap'>
          <pose>8.16469 3.87335 1.4933 -0.002825 -0.530503 -0.00063</pose>
          <velocity>-0.001013 -0.00486 -0.006053 0.00488 0.00482 0.002145</velocity>
          <acceleration>0.614004 0.168695 -2.96438 0.084596 0.842551 -0.005163</acceleration>
          <wrench>1.22801 0.337389 -5.92875 0 -0 0</wrench>
        </link>
        <link name='rudder'>
          <pose>7.6773 3.84439 0.492426 0.001336 -0.000609 -0.014967</pose>
          <velocity>-0.006838 -0.211507 -0.001898 0.01905 0.003169 -0.036621</velocity>
          <acceleration>0.538042 0.024574 3.35015 -0.357561 1.45902 1.17724</acceleration>
          <wrench>1.07608 0.049149 6.70029 0 -0 0</wrench>
        </link>
      </model>
      <model name='ground_plane'>
        <pose>0 0 0 0 -0 0</pose>
        <scale>1 1 1</scale>
        <link name='link'>
          <pose>0 0 0 0 -0 0</pose>
          <velocity>0 0 0 0 -0 0</velocity>
          <acceleration>nan nan nan nan nan nan</acceleration>
          <wrench>0 0 0 0 -0 0</wrench>
        </link>
      </model>
      <model name='model'>
        <pose>-0.896162 -2.38521 0.199998 0 -0 0</pose>
        <scale>1 1 1</scale>
        <link name='link_1'>
          <pose>-0.896162 -2.38521 0.199998 0 -0 0</pose>
          <velocity>0 1e-05 -0.007009 -5e-05 0 0</velocity>
          <acceleration>0 0.000408 -9.79991 5.2e-05 -0 0</acceleration>
          <wrench>0 0.000408 -9.79991 0 -0 0</wrench>
        </link>
        <link name='link_3_clone'>
          <pose>-0.896162 -1.83519 0.199998 0 -0 0</pose>
          <velocity>0 9e-06 -0.007036 -5.1e-05 0 0</velocity>
          <acceleration>0 -0.000255 -9.79958 -0.001653 0 0</acceleration>
          <wrench>0 -0.000255 -9.79958 0 -0 0</wrench>
        </link>
        <link name='link_3_clone_clone'>
          <pose>-0.896162 -2.93523 0.199998 0 -0 0</pose>
          <velocity>0 9e-06 -0.006982 -5.1e-05 0 0</velocity>
          <acceleration>0 -0.000153 -9.80051 -0.001904 0 0</acceleration>
          <wrench>0 -0.000153 -9.80051 0 -0 0</wrench>
        </link>
      </model>
      <model name='model_clone'>
        <pose>0.416005 -2.7668 0.200005 0 -0 0</pose>
        <scale>1 1 1</scale>
        <link name='link_1'>
          <pose>0.416005 -2.7668 0.200005 0 -0 0</pose>
          <velocity>0 -1.1e-05 0.007034 5e-05 -0 0</velocity>
          <acceleration>0 -0.040724 14.0682 0.100754 -0 0</acceleration>
          <wrench>0 -0.040724 14.0682 0 -0 0</wrench>
        </link>
        <link name='link_3_clone'>
          <pose>0.416005 -2.21678 0.200005 0 -0 0</pose>
          <velocity>0 -1e-05 0.007062 5.1e-05 -0 0</velocity>
          <acceleration>0 -0.040064 14.1234 0.10245 -0 0</acceleration>
          <wrench>0 -0.040064 14.1234 0 -0 0</wrench>
        </link>
        <link name='link_3_clone_clone'>
          <pose>0.416005 -3.31682 0.200005 0 -0 0</pose>
          <velocity>0 -1e-05 0.007007 5.1e-05 -0 0</velocity>
          <acceleration>0 -0.040165 14.0134 0.102699 -0 0</acceleration>
          <wrench>0 -0.040165 14.0134 0 -0 0</wrench>
        </link>
      </model>
      <light name='sun'>
        <pose>0 0 10 0 -0 0</pose>
      </light>
    </state>
    <gui fullscreen='0'>
      <camera name='user_camera'>
        <pose>19.8303 -12.3539 32.8742 0 1.05564 2.64019</pose>
        <view_controller>orbit</view_controller>
        <projection_type>perspective</projection_type>
      </camera>
    </gui>
    <model name='model'>
      <link name='link_1'>
        <inertial>
          <mass>1</mass>
          <inertia>
            <ixx>0.166667</ixx>
            <ixy>0</ixy>
            <ixz>0</ixz>
            <iyy>0.166667</iyy>
            <iyz>0</iyz>
            <izz>0.166667</izz>
          </inertia>
          <pose>0 0 0.2 0 -0 0</pose>
        </inertial>
        <pose>0 0 0 0 -0 0</pose>
        <gravity>1</gravity>
        <self_collide>0</self_collide>
        <kinematic>0</kinematic>
        <enable_wind>0</enable_wind>
        <visual name='visual'>
          <pose>0 0 0 0 -0 0</pose>
          <geometry>
            <box>
              <size>0.3 1 0.1</size>
            </box>
          </geometry>
          <material>
            <lighting>1</lighting>
            <script>
              <uri>file://media/materials/scripts/gazebo.material</uri>
              <name>Gazebo/Grey</name>
            </script>
            <shader type='pixel'>
              <normal_map>__default__</normal_map>
            </shader>
            <ambient>0.3 0.3 0.3 1</ambient>
            <diffuse>0.7 0.7 0.7 1</diffuse>
            <specular>0.01 0.01 0.01 1</specular>
            <emissive>0 0 0 1</emissive>
          </material>
          <transparency>0</transparency>
          <cast_shadows>1</cast_shadows>
        </visual>
        <collision name='collision'>
          <laser_retro>0</laser_retro>
          <max_contacts>10</max_contacts>
          <pose>0 0 0 0 -0 0</pose>
          <geometry>
            <box>
              <size>0.3 1 0.1</size>
            </box>
          </geometry>
          <surface>
            <friction>
              <ode>
                <mu>1</mu>
                <mu2>1</mu2>
                <fdir1>0 0 0</fdir1>
                <slip1>0</slip1>
                <slip2>0</slip2>
              </ode>
              <torsional>
                <coefficient>1</coefficient>
                <patch_radius>0</patch_radius>
                <surface_radius>0</surface_radius>
                <use_patch_radius>1</use_patch_radius>
                <ode>
                  <slip>0</slip>
                </ode>
              </torsional>
            </friction>
            <bounce>
              <restitution_coefficient>0</restitution_coefficient>
              <threshold>1e+06</threshold>
            </bounce>
            <contact>
              <collide_without_contact>0</collide_without_contact>
              <collide_without_contact_bitmask>1</collide_without_contact_bitmask>
              <collide_bitmask>1</collide_bitmask>
              <ode>
                <soft_cfm>0</soft_cfm>
                <soft_erp>0.2</soft_erp>
                <kp>1e+13</kp>
                <kd>1</kd>
                <max_vel>0.01</max_vel>
                <min_depth>0</min_depth>
              </ode>
              <bullet>
                <split_impulse>1</split_impulse>
                <split_impulse_penetration_threshold>-0.01</split_impulse_penetration_threshold>
                <soft_cfm>0</soft_cfm>
                <soft_erp>0.2</soft_erp>
                <kp>1e+13</kp>
                <kd>1</kd>
              </bullet>
            </contact>
          </surface>
        </collision>
      </link>
      <link name='link_3_clone'>
        <inertial>
          <mass>1</mass>
          <inertia>
            <ixx>0.145833</ixx>
            <ixy>0</ixy>
            <ixz>0</ixz>
            <iyy>0.145833</iyy>
            <iyz>0</iyz>
            <izz>0.125</izz>
          </inertia>
          <pose>0 0 0.2 1.5707 -0 0</pose>
        </inertial>
        <pose>0 0.55002 0 0 -0 0</pose>
        <gravity>1</gravity>
        <self_collide>0</self_collide>
        <kinematic>0</kinematic>
        <enable_wind>0</enable_wind>
        <visual name='visual'>
          <pose>0 0 0 1.5707 -0 0</pose>
          <geometry>
            <cylinder>
              <radius>0.2</radius>
              <length>0.1</length>
            </cylinder>
          </geometry>
          <material>
            <lighting>1</lighting>
            <script>
              <uri>file://media/materials/scripts/gazebo.material</uri>
              <name>Gazebo/Grey</name>
            </script>
            <shader type='pixel'>
              <normal_map>__default__</normal_map>
            </shader>
            <ambient>0.3 0.3 0.3 1</ambient>
            <diffuse>0.7 0.7 0.7 1</diffuse>
            <specular>0.01 0.01 0.01 1</specular>
            <emissive>0 0 0 1</emissive>
          </material>
          <transparency>0</transparency>
          <cast_shadows>1</cast_shadows>
        </visual>
        <collision name='collision'>
          <laser_retro>0</laser_retro>
          <max_contacts>10</max_contacts>
          <pose>0 0 0 1.5707 -0 0</pose>
          <geometry>
            <cylinder>
              <radius>0.2</radius>
              <length>0.1</length>
            </cylinder>
          </geometry>
          <surface>
            <friction>
              <ode>
                <mu>1</mu>
                <mu2>1</mu2>
                <fdir1>0 0 0</fdir1>
                <slip1>0</slip1>
                <slip2>0</slip2>
              </ode>
              <torsional>
                <coefficient>1</coefficient>
                <patch_radius>0</patch_radius>
                <surface_radius>0</surface_radius>
                <use_patch_radius>1</use_patch_radius>
                <ode>
                  <slip>0</slip>
                </ode>
              </torsional>
            </friction>
            <bounce>
              <restitution_coefficient>0</restitution_coefficient>
              <threshold>1e+06</threshold>
            </bounce>
            <contact>
              <collide_without_contact>0</collide_without_contact>
              <collide_without_contact_bitmask>1</collide_without_contact_bitmask>
              <collide_bitmask>1</collide_bitmask>
              <ode>
                <soft_cfm>0</soft_cfm>
                <soft_erp>0.2</soft_erp>
                <kp>1e+13</kp>
                <kd>1</kd>
                <max_vel>0.01</max_vel>
                <min_depth>0</min_depth>
              </ode>
              <bullet>
                <split_impulse>1</split_impulse>
                <split_impulse_penetration_threshold>-0.01</split_impulse_penetration_threshold>
                <soft_cfm>0</soft_cfm>
                <soft_erp>0.2</soft_erp>
                <kp>1e+13</kp>
                <kd>1</kd>
              </bullet>
            </contact>
          </surface>
        </collision>
      </link>
      <link name='link_3_clone_clone'>
        <inertial>
          <mass>1</mass>
          <inertia>
            <ixx>0.145833</ixx>
            <ixy>0</ixy>
            <ixz>0</ixz>
            <iyy>0.145833</iyy>
            <iyz>0</iyz>
            <izz>0.125</izz>
          </inertia>
          <pose>0 0 0.2 1.5707 -0 0</pose>
        </inertial>
        <pose>0 -0.550019 0 0 -0 0</pose>
        <gravity>1</gravity>
        <self_collide>0</self_collide>
        <kinematic>0</kinematic>
        <enable_wind>0</enable_wind>
        <visual name='visual'>
          <pose>0 0 0 1.5707 -0 0</pose>
          <geometry>
            <cylinder>
              <radius>0.2</radius>
              <length>0.1</length>
            </cylinder>
          </geometry>
          <material>
            <lighting>1</lighting>
            <script>
              <uri>file://media/materials/scripts/gazebo.material</uri>
              <name>Gazebo/Grey</name>
            </script>
            <shader type='pixel'>
              <normal_map>__default__</normal_map>
            </shader>
            <ambient>0.3 0.3 0.3 1</ambient>
            <diffuse>0.7 0.7 0.7 1</diffuse>
            <specular>0.01 0.01 0.01 1</specular>
            <emissive>0 0 0 1</emissive>
          </material>
          <transparency>0</transparency>
          <cast_shadows>1</cast_shadows>
        </visual>
        <collision name='collision'>
          <laser_retro>0</laser_retro>
          <max_contacts>10</max_contacts>
          <pose>0 0 0 1.5707 -0 0</pose>
          <geometry>
            <cylinder>
              <radius>0.2</radius>
              <length>0.1</length>
            </cylinder>
          </geometry>
          <surface>
            <friction>
              <ode>
                <mu>1</mu>
                <mu2>1</mu2>
                <fdir1>0 0 0</fdir1>
                <slip1>0</slip1>
                <slip2>0</slip2>
              </ode>
              <torsional>
                <coefficient>1</coefficient>
                <patch_radius>0</patch_radius>
                <surface_radius>0</surface_radius>
                <use_patch_radius>1</use_patch_radius>
                <ode>
                  <slip>0</slip>
                </ode>
              </torsional>
            </friction>
            <bounce>
              <restitution_coefficient>0</restitution_coefficient>
              <threshold>1e+06</threshold>
            </bounce>
            <contact>
              <collide_without_contact>0</collide_without_contact>
              <collide_without_contact_bitmask>1</collide_without_contact_bitmask>
              <collide_bitmask>1</collide_bitmask>
              <ode>
                <soft_cfm>0</soft_cfm>
                <soft_erp>0.2</soft_erp>
                <kp>1e+13</kp>
                <kd>1</kd>
                <max_vel>0.01</max_vel>
                <min_depth>0</min_depth>
              </ode>
              <bullet>
                <split_impulse>1</split_impulse>
                <split_impulse_penetration_threshold>-0.01</split_impulse_penetration_threshold>
                <soft_cfm>0</soft_cfm>
                <soft_erp>0.2</soft_erp>
                <kp>1e+13</kp>
                <kd>1</kd>
              </bullet>
            </contact>
          </surface>
        </collision>
      </link>
      <joint name='link_1_JOINT_1' type='revolute'>
        <parent>link_1</parent>
        <child>link_3_clone</child>
        <pose>0 0 0 0 -0 0</pose>
        <axis>
          <xyz>0 0 1</xyz>
          <limit>
            <lower>-1.79769e+308</lower>
            <upper>1.79769e+308</upper>
            <effort>-1</effort>
            <velocity>-1</velocity>
          </limit>
          <dynamics>
            <spring_reference>0</spring_reference>
            <spring_stiffness>0</spring_stiffness>
            <damping>0</damping>
          </dynamics>
        </axis>
        <physics>
          <ode>
            <limit>
              <cfm>0</cfm>
              <erp>0.2</erp>
            </limit>
            <suspension>
              <cfm>0</cfm>
              <erp>0.2</erp>
            </suspension>
          </ode>
        </physics>
      </joint>
      <joint name='link_1_JOINT_2' type='revolute'>
        <parent>link_1</parent>
        <child>link_3_clone_clone</child>
        <pose>0 0 0 0 -0 0</pose>
        <axis>
          <xyz>0 0 1</xyz>
          <limit>
            <lower>-1.79769e+308</lower>
            <upper>1.79769e+308</upper>
            <effort>-1</effort>
            <velocity>-1</velocity>
          </limit>
          <dynamics>
            <spring_reference>0</spring_reference>
            <spring_stiffness>0</spring_stiffness>
            <damping>0</damping>
            <friction>0</friction>
          </dynamics>
        </axis>
        <physics>
          <ode>
            <limit>
              <cfm>0</cfm>
              <erp>0.2</erp>
            </limit>
            <suspension>
              <cfm>0</cfm>
              <erp>0.2</erp>
            </suspension>
          </ode>
        </physics>
      </joint>
      <static>0</static>
      <allow_auto_disable>1</allow_auto_disable>
      <pose>-0.896162 -2.3851 0.5 0 -0 0</pose>
    </model>
    <model name='model_clone'>
      <link name='link_1'>
        <inertial>
          <mass>1</mass>
          <inertia>
            <ixx>0.166667</ixx>
            <ixy>0</ixy>
            <ixz>0</ixz>
            <iyy>0.166667</iyy>
            <iyz>0</iyz>
            <izz>0.166667</izz>
          </inertia>
          <pose>0 0 0.2 0 -0 0</pose>
        </inertial>
        <pose>0 0 0 0 -0 0</pose>
        <gravity>1</gravity>
        <self_collide>0</self_collide>
        <kinematic>0</kinematic>
        <enable_wind>0</enable_wind>
        <visual name='visual'>
          <pose>0 0 0 0 -0 0</pose>
          <geometry>
            <box>
              <size>0.3 1 0.1</size>
            </box>
          </geometry>
          <material>
            <lighting>1</lighting>
            <script>
              <uri>file://media/materials/scripts/gazebo.material</uri>
              <name>Gazebo/Grey</name>
            </script>
            <shader type='pixel'>
              <normal_map>__default__</normal_map>
            </shader>
            <ambient>0.3 0.3 0.3 1</ambient>
            <diffuse>0.7 0.7 0.7 1</diffuse>
            <specular>0.01 0.01 0.01 1</specular>
            <emissive>0 0 0 1</emissive>
          </material>
          <transparency>0</transparency>
          <cast_shadows>1</cast_shadows>
        </visual>
        <collision name='collision'>
          <laser_retro>0</laser_retro>
          <max_contacts>10</max_contacts>
          <pose>0 0 0 0 -0 0</pose>
          <geometry>
            <box>
              <size>0.3 1 0.1</size>
            </box>
          </geometry>
          <surface>
            <friction>
              <ode>
                <mu>1</mu>
                <mu2>1</mu2>
                <fdir1>0 0 0</fdir1>
                <slip1>0</slip1>
                <slip2>0</slip2>
              </ode>
              <torsional>
                <coefficient>1</coefficient>
                <patch_radius>0</patch_radius>
                <surface_radius>0</surface_radius>
                <use_patch_radius>1</use_patch_radius>
                <ode>
                  <slip>0</slip>
                </ode>
              </torsional>
            </friction>
            <bounce>
              <restitution_coefficient>0</restitution_coefficient>
              <threshold>1e+06</threshold>
            </bounce>
            <contact>
              <collide_without_contact>0</collide_without_contact>
              <collide_without_contact_bitmask>1</collide_without_contact_bitmask>
              <collide_bitmask>1</collide_bitmask>
              <ode>
                <soft_cfm>0</soft_cfm>
                <soft_erp>0.2</soft_erp>
                <kp>1e+13</kp>
                <kd>1</kd>
                <max_vel>0.01</max_vel>
                <min_depth>0</min_depth>
              </ode>
              <bullet>
                <split_impulse>1</split_impulse>
                <split_impulse_penetration_threshold>-0.01</split_impulse_penetration_threshold>
                <soft_cfm>0</soft_cfm>
                <soft_erp>0.2</soft_erp>
                <kp>1e+13</kp>
                <kd>1</kd>
              </bullet>
            </contact>
          </surface>
        </collision>
      </link>
      <link name='link_3_clone'>
        <inertial>
          <mass>1</mass>
          <inertia>
            <ixx>0.145833</ixx>
            <ixy>0</ixy>
            <ixz>0</ixz>
            <iyy>0.145833</iyy>
            <iyz>0</iyz>
            <izz>0.125</izz>
          </inertia>
          <pose>0 0 0.2 1.5707 -0 0</pose>
        </inertial>
        <pose>0 0.55002 0 0 -0 0</pose>
        <gravity>1</gravity>
        <self_collide>0</self_collide>
        <kinematic>0</kinematic>
        <enable_wind>0</enable_wind>
        <visual name='visual'>
          <pose>0 0 0 1.5707 -0 0</pose>
          <geometry>
            <cylinder>
              <radius>0.2</radius>
              <length>0.1</length>
            </cylinder>
          </geometry>
          <material>
            <lighting>1</lighting>
            <script>
              <uri>file://media/materials/scripts/gazebo.material</uri>
              <name>Gazebo/Grey</name>
            </script>
            <shader type='pixel'>
              <normal_map>__default__</normal_map>
            </shader>
            <ambient>0.3 0.3 0.3 1</ambient>
            <diffuse>0.7 0.7 0.7 1</diffuse>
            <specular>0.01 0.01 0.01 1</specular>
            <emissive>0 0 0 1</emissive>
          </material>
          <transparency>0</transparency>
          <cast_shadows>1</cast_shadows>
        </visual>
        <collision name='collision'>
          <laser_retro>0</laser_retro>
          <max_contacts>10</max_contacts>
          <pose>0 0 0 1.5707 -0 0</pose>
          <geometry>
            <cylinder>
              <radius>0.2</radius>
              <length>0.1</length>
            </cylinder>
          </geometry>
          <surface>
            <friction>
              <ode>
                <mu>1</mu>
                <mu2>1</mu2>
                <fdir1>0 0 0</fdir1>
                <slip1>0</slip1>
                <slip2>0</slip2>
              </ode>
              <torsional>
                <coefficient>1</coefficient>
                <patch_radius>0</patch_radius>
                <surface_radius>0</surface_radius>
                <use_patch_radius>1</use_patch_radius>
                <ode>
                  <slip>0</slip>
                </ode>
              </torsional>
            </friction>
            <bounce>
              <restitution_coefficient>0</restitution_coefficient>
              <threshold>1e+06</threshold>
            </bounce>
            <contact>
              <collide_without_contact>0</collide_without_contact>
              <collide_without_contact_bitmask>1</collide_without_contact_bitmask>
              <collide_bitmask>1</collide_bitmask>
              <ode>
                <soft_cfm>0</soft_cfm>
                <soft_erp>0.2</soft_erp>
                <kp>1e+13</kp>
                <kd>1</kd>
                <max_vel>0.01</max_vel>
                <min_depth>0</min_depth>
              </ode>
              <bullet>
                <split_impulse>1</split_impulse>
                <split_impulse_penetration_threshold>-0.01</split_impulse_penetration_threshold>
                <soft_cfm>0</soft_cfm>
                <soft_erp>0.2</soft_erp>
                <kp>1e+13</kp>
                <kd>1</kd>
              </bullet>
            </contact>
          </surface>
        </collision>
      </link>
      <link name='link_3_clone_clone'>
        <inertial>
          <mass>1</mass>
          <inertia>
            <ixx>0.145833</ixx>
            <ixy>0</ixy>
            <ixz>0</ixz>
            <iyy>0.145833</iyy>
            <iyz>0</iyz>
            <izz>0.125</izz>
          </inertia>
          <pose>0 0 0.2 1.5707 -0 0</pose>
        </inertial>
        <pose>0 -0.550019 0 0 -0 0</pose>
        <gravity>1</gravity>
        <self_collide>0</self_collide>
        <kinematic>0</kinematic>
        <enable_wind>0</enable_wind>
        <visual name='visual'>
          <pose>0 0 0 1.5707 -0 0</pose>
          <geometry>
            <cylinder>
              <radius>0.2</radius>
              <length>0.1</length>
            </cylinder>
          </geometry>
          <material>
            <lighting>1</lighting>
            <script>
              <uri>file://media/materials/scripts/gazebo.material</uri>
              <name>Gazebo/Grey</name>
            </script>
            <shader type='pixel'>
              <normal_map>__default__</normal_map>
            </shader>
            <ambient>0.3 0.3 0.3 1</ambient>
            <diffuse>0.7 0.7 0.7 1</diffuse>
            <specular>0.01 0.01 0.01 1</specular>
            <emissive>0 0 0 1</emissive>
          </material>
          <transparency>0</transparency>
          <cast_shadows>1</cast_shadows>
        </visual>
        <collision name='collision'>
          <laser_retro>0</laser_retro>
          <max_contacts>10</max_contacts>
          <pose>0 0 0 1.5707 -0 0</pose>
          <geometry>
            <cylinder>
              <radius>0.2</radius>
              <length>0.1</length>
            </cylinder>
          </geometry>
          <surface>
            <friction>
              <ode>
                <mu>1</mu>
                <mu2>1</mu2>
                <fdir1>0 0 0</fdir1>
                <slip1>0</slip1>
                <slip2>0</slip2>
              </ode>
              <torsional>
                <coefficient>1</coefficient>
                <patch_radius>0</patch_radius>
                <surface_radius>0</surface_radius>
                <use_patch_radius>1</use_patch_radius>
                <ode>
                  <slip>0</slip>
                </ode>
              </torsional>
            </friction>
            <bounce>
              <restitution_coefficient>0</restitution_coefficient>
              <threshold>1e+06</threshold>
            </bounce>
            <contact>
              <collide_without_contact>0</collide_without_contact>
              <collide_without_contact_bitmask>1</collide_without_contact_bitmask>
              <collide_bitmask>1</collide_bitmask>
              <ode>
                <soft_cfm>0</soft_cfm>
                <soft_erp>0.2</soft_erp>
                <kp>1e+13</kp>
                <kd>1</kd>
                <max_vel>0.01</max_vel>
                <min_depth>0</min_depth>
              </ode>
              <bullet>
                <split_impulse>1</split_impulse>
                <split_impulse_penetration_threshold>-0.01</split_impulse_penetration_threshold>
                <soft_cfm>0</soft_cfm>
                <soft_erp>0.2</soft_erp>
                <kp>1e+13</kp>
                <kd>1</kd>
              </bullet>
            </contact>
          </surface>
        </collision>
      </link>
      <joint name='link_1_JOINT_1' type='revolute'>
        <parent>link_1</parent>
        <child>link_3_clone</child>
        <pose>0 0 0 0 -0 0</pose>
        <axis>
          <xyz>0 0 1</xyz>
          <limit>
            <lower>-1.79769e+308</lower>
            <upper>1.79769e+308</upper>
            <effort>-1</effort>
            <velocity>-1</velocity>
          </limit>
          <dynamics>
            <spring_reference>0</spring_reference>
            <spring_stiffness>0</spring_stiffness>
            <damping>0</damping>
          </dynamics>
        </axis>
        <physics>
          <ode>
            <limit>
              <cfm>0</cfm>
              <erp>0.2</erp>
            </limit>
            <suspension>
              <cfm>0</cfm>
              <erp>0.2</erp>
            </suspension>
          </ode>
        </physics>
      </joint>
      <joint name='link_1_JOINT_2' type='revolute'>
        <parent>link_1</parent>
        <child>link_3_clone_clone</child>
        <pose>0 0 0 0 -0 0</pose>
        <axis>
          <xyz>0 0 1</xyz>
          <limit>
            <lower>-1.79769e+308</lower>
            <upper>1.79769e+308</upper>
            <effort>-1</effort>
            <velocity>-1</velocity>
          </limit>
          <dynamics>
            <spring_reference>0</spring_reference>
            <spring_stiffness>0</spring_stiffness>
            <damping>0</damping>
            <friction>0</friction>
          </dynamics>
        </axis>
        <physics>
          <ode>
            <limit>
              <cfm>0</cfm>
              <erp>0.2</erp>
            </limit>
            <suspension>
              <cfm>0</cfm>
              <erp>0.2</erp>
            </suspension>
          </ode>
        </physics>
      </joint>
      <static>0</static>
      <allow_auto_disable>1</allow_auto_disable>
      <pose>0.416005 -2.76671 0.199996 0 -0 0</pose>
    </model>
    <model name='ambulance'>
      <static>1</static>
      <link name='link'>
        <collision name='collision'>
          <geometry>
            <mesh>
              <scale>0.0254 0.0254 0.0254</scale>
              <uri>model://ambulance/meshes/ambulance.obj</uri>
            </mesh>
          </geometry>
          <max_contacts>10</max_contacts>
          <surface>
            <contact>
              <ode/>
            </contact>
            <bounce/>
            <friction>
              <torsional>
                <ode/>
              </torsional>
              <ode/>
            </friction>
          </surface>
        </collision>
        <visual name='visual'>
          <geometry>
            <mesh>
              <scale>0.0254 0.0254 0.0254</scale>
              <uri>model://ambulance/meshes/ambulance.obj</uri>
            </mesh>
          </geometry>
        </visual>
        <self_collide>0</self_collide>
        <enable_wind>0</enable_wind>
        <kinematic>0</kinematic>
      </link>
      <pose>-7.8224 -4.0409 0 0 -0 0</pose>
    </model>
    <model name='cessna_c172'>
      <pose>7.71543 3.88079 0.495 0 -0 0</pose>
      <link name='body'>
        <inertial>
          <mass>680.389</mass>
          <inertia>
            <ixx>1285.32</ixx>
            <ixy>0</ixy>
            <iyy>1824.93</iyy>
            <ixz>0</ixz>
            <iyz>0</iyz>
            <izz>2666.89</izz>
          </inertia>
          <pose>-0.0414 0 0.9271 0 -0 0</pose>
        </inertial>
        <collision name='collision'>
          <geometry>
            <mesh>
              <uri>model://cessna/meshes/body.dae</uri>
            </mesh>
          </geometry>
          <max_contacts>10</max_contacts>
          <surface>
            <contact>
              <ode/>
            </contact>
            <bounce/>
            <friction>
              <torsional>
                <ode/>
              </torsional>
              <ode/>
            </friction>
          </surface>
        </collision>
        <visual name='visual'>
          <geometry>
            <mesh>
              <uri>model://cessna/meshes/body.dae</uri>
            </mesh>
          </geometry>
        </visual>
        <self_collide>0</self_collide>
        <enable_wind>0</enable_wind>
        <kinematic>0</kinematic>
      </link>
      <link name='left_aileron'>
        <inertial>
          <mass>2</mass>
          <inertia>
            <ixx>0.8434</ixx>
            <ixy>0</ixy>
            <iyy>0.0119</iyy>
            <ixz>0</ixz>
            <iyz>0</iyz>
            <izz>0.855</izz>
          </inertia>
          <pose>-1.65 3.7 1.5 0.05 -0 -0.12</pose>
        </inertial>
        <collision name='collision'>
          <geometry>
            <mesh>
              <uri>model://cessna/meshes/left_aileron.dae</uri>
            </mesh>
          </geometry>
          <max_contacts>10</max_contacts>
          <surface>
            <contact>
              <ode/>
            </contact>
            <bounce/>
            <friction>
              <torsional>
                <ode/>
              </torsional>
              <ode/>
            </friction>
          </surface>
        </collision>
        <visual name='visual'>
          <geometry>
            <mesh>
              <uri>model://cessna/meshes/left_aileron.dae</uri>
            </mesh>
          </geometry>
        </visual>
        <self_collide>0</self_collide>
        <enable_wind>0</enable_wind>
        <kinematic>0</kinematic>
      </link>
      <link name='left_flap'>
        <inertial>
          <mass>2</mass>
          <inertia>
            <ixx>0.6747</ixx>
            <ixy>0</ixy>
            <iyy>0.0242</iyy>
            <ixz>0</ixz>
            <iyz>0</iyz>
            <izz>0.6962</izz>
          </inertia>
          <pose>-1.8 1.55 1.43 0.02 -0 0</pose>
        </inertial>
        <collision name='collision'>
          <geometry>
            <mesh>
              <uri>model://cessna/meshes/left_flap.dae</uri>
            </mesh>
          </geometry>
          <max_contacts>10</max_contacts>
          <surface>
            <contact>
              <ode/>
            </contact>
            <bounce/>
            <friction>
              <torsional>
                <ode/>
              </torsional>
              <ode/>
            </friction>
          </surface>
        </collision>
        <visual name='visual'>
          <geometry>
            <mesh>
              <uri>model://cessna/meshes/left_flap.dae</uri>
            </mesh>
          </geometry>
        </visual>
        <self_collide>0</self_collide>
        <enable_wind>0</enable_wind>
        <kinematic>0</kinematic>
      </link>
      <link name='right_aileron'>
        <inertial>
          <mass>2</mass>
          <inertia>
            <ixx>0.8434</ixx>
            <ixy>0</ixy>
            <iyy>0.0119</iyy>
            <ixz>0</ixz>
            <iyz>0</iyz>
            <izz>0.855</izz>
          </inertia>
          <pose>-1.65 -3.7 1.5 -0.05 -0 0.12</pose>
        </inertial>
        <collision name='collision'>
          <geometry>
            <mesh>
              <uri>model://cessna/meshes/right_aileron.dae</uri>
            </mesh>
          </geometry>
          <max_contacts>10</max_contacts>
          <surface>
            <contact>
              <ode/>
            </contact>
            <bounce/>
            <friction>
              <torsional>
                <ode/>
              </torsional>
              <ode/>
            </friction>
          </surface>
        </collision>
        <visual name='visual'>
          <geometry>
            <mesh>
              <uri>model://cessna/meshes/right_aileron.dae</uri>
            </mesh>
          </geometry>
        </visual>
        <self_collide>0</self_collide>
        <enable_wind>0</enable_wind>
        <kinematic>0</kinematic>
      </link>
      <link name='right_flap'>
        <inertial>
          <mass>2</mass>
          <inertia>
            <ixx>0.6747</ixx>
            <ixy>0</ixy>
            <iyy>0.0242</iyy>
            <ixz>0</ixz>
            <iyz>0</iyz>
            <izz>0.6962</izz>
          </inertia>
          <pose>-1.8 -1.55 1.43 -0.02 0 0</pose>
        </inertial>
        <collision name='collision'>
          <geometry>
            <mesh>
              <uri>model://cessna/meshes/right_flap.dae</uri>
            </mesh>
          </geometry>
          <max_contacts>10</max_contacts>
          <surface>
            <contact>
              <ode/>
            </contact>
            <bounce/>
            <friction>
              <torsional>
                <ode/>
              </torsional>
              <ode/>
            </friction>
          </surface>
        </collision>
        <visual name='visual'>
          <geometry>
            <mesh>
              <uri>model://cessna/meshes/right_flap.dae</uri>
            </mesh>
          </geometry>
        </visual>
        <self_collide>0</self_collide>
        <enable_wind>0</enable_wind>
        <kinematic>0</kinematic>
      </link>
      <link name='elevators'>
        <inertial>
          <mass>2</mass>
          <inertia>
            <ixx>1.5008</ixx>
            <ixy>0</ixy>
            <iyy>0.0274</iyy>
            <ixz>0</ixz>
            <iyz>0</iyz>
            <izz>1.5266</izz>
          </inertia>
          <pose>-5.75 0 0.57 0 -0 0</pose>
        </inertial>
        <collision name='collision'>
          <geometry>
            <mesh>
              <uri>model://cessna/meshes/elevators.dae</uri>
            </mesh>
          </geometry>
          <max_contacts>10</max_contacts>
          <surface>
            <contact>
              <ode/>
            </contact>
            <bounce/>
            <friction>
              <torsional>
                <ode/>
              </torsional>
              <ode/>
            </friction>
          </surface>
        </collision>
        <visual name='visual'>
          <geometry>
            <mesh>
              <uri>model://cessna/meshes/elevators.dae</uri>
            </mesh>
          </geometry>
        </visual>
        <self_collide>0</self_collide>
        <enable_wind>0</enable_wind>
        <kinematic>0</kinematic>
      </link>
      <link name='rudder'>
        <inertial>
          <mass>2</mass>
          <inertia>
            <ixx>0.4708</ixx>
            <ixy>0</ixy>
            <iyy>0.5208</iyy>
            <ixz>0</ixz>
            <iyz>0</iyz>
            <izz>0.0508</izz>
          </inertia>
          <pose>-6.1 0 1.3 0 -0.35 0</pose>
        </inertial>
        <collision name='collision'>
          <geometry>
            <mesh>
              <uri>model://cessna/meshes/rudder.dae</uri>
            </mesh>
          </geometry>
          <max_contacts>10</max_contacts>
          <surface>
            <contact>
              <ode/>
            </contact>
            <bounce/>
            <friction>
              <torsional>
                <ode/>
              </torsional>
              <ode/>
            </friction>
          </surface>
        </collision>
        <visual name='visual'>
          <geometry>
            <mesh>
              <uri>model://cessna/meshes/rudder.dae</uri>
            </mesh>
          </geometry>
        </visual>
        <self_collide>0</self_collide>
        <enable_wind>0</enable_wind>
        <kinematic>0</kinematic>
      </link>
      <link name='propeller'>
        <pose>1.79 0 0.855 0 -0 0</pose>
        <inertial>
          <mass>18.37</mass>
          <inertia>
            <ixx>7.5067</ixx>
            <ixy>0</ixy>
            <iyy>7.515</iyy>
            <ixz>0</ixz>
            <iyz>0</iyz>
            <izz>0.068275</izz>
          </inertia>
          <pose>-0.35 0 0 0 -0 0</pose>
        </inertial>
        <collision name='collision'>
          <geometry>
            <mesh>
              <uri>model://cessna/meshes/cessna_prop.dae</uri>
            </mesh>
          </geometry>
          <max_contacts>10</max_contacts>
          <surface>
            <contact>
              <ode/>
            </contact>
            <bounce/>
            <friction>
              <torsional>
                <ode/>
              </torsional>
              <ode/>
            </friction>
          </surface>
        </collision>
        <visual name='visual'>
          <geometry>
            <mesh>
              <uri>model://cessna/meshes/cessna_prop.dae</uri>
            </mesh>
          </geometry>
        </visual>
        <self_collide>0</self_collide>
        <enable_wind>0</enable_wind>
        <kinematic>0</kinematic>
      </link>
      <link name='front_wheel'>
        <inertial>
          <mass>2</mass>
          <inertia>
            <ixx>0.01786</ixx>
            <ixy>0</ixy>
            <iyy>0.01786</iyy>
            <ixz>0</ixz>
            <iyz>0</iyz>
            <izz>0.0324</izz>
          </inertia>
          <pose>0.712 0 -0.313 1.57079 -0 0</pose>
        </inertial>
        <collision name='collision'>
          <pose>0.712 0 -0.313 1.57079 -0 0</pose>
          <geometry>
            <cylinder>
              <radius>0.18</radius>
              <length>0.1</length>
            </cylinder>
          </geometry>
          <surface>
            <friction>
              <ode>
                <mu>0.3</mu>
                <mu2>0.3</mu2>
              </ode>
              <torsional>
                <ode/>
              </torsional>
            </friction>
            <contact>
              <ode>
                <max_vel>0.1</max_vel>
                <min_depth>0.001</min_depth>
              </ode>
            </contact>
            <bounce/>
          </surface>
          <max_contacts>10</max_contacts>
        </collision>
        <visual name='visual'>
          <geometry>
            <mesh>
              <uri>model://cessna/meshes/cessna_front_wheel.dae</uri>
            </mesh>
          </geometry>
        </visual>
        <self_collide>0</self_collide>
        <enable_wind>0</enable_wind>
        <kinematic>0</kinematic>
      </link>
      <link name='rear_left_wheel'>
        <inertial>
          <mass>2</mass>
          <inertia>
            <ixx>0.035516</ixx>
            <ixy>0</ixy>
            <iyy>0.035516</iyy>
            <ixz>0</ixz>
            <iyz>0</iyz>
            <izz>0.0625</izz>
          </inertia>
          <pose>-1 1.27 -0.25 1.57079 -0 0</pose>
        </inertial>
        <collision name='collision'>
          <pose>-1 1.27 -0.25 1.57079 -0 0</pose>
          <geometry>
            <cylinder>
              <radius>0.25</radius>
              <length>0.16</length>
            </cylinder>
          </geometry>
          <surface>
            <friction>
              <ode>
                <mu>0.3</mu>
                <mu2>0.3</mu2>
              </ode>
              <torsional>
                <ode/>
              </torsional>
            </friction>
            <contact>
              <ode>
                <max_vel>0.1</max_vel>
                <min_depth>0.001</min_depth>
              </ode>
            </contact>
            <bounce/>
          </surface>
          <max_contacts>10</max_contacts>
        </collision>
        <visual name='visual'>
          <geometry>
            <mesh>
              <uri>model://cessna/meshes/cessna_rear_left_wheel.dae</uri>
            </mesh>
          </geometry>
        </visual>
        <self_collide>0</self_collide>
        <enable_wind>0</enable_wind>
        <kinematic>0</kinematic>
      </link>
      <link name='rear_right_wheel'>
        <inertial>
          <mass>2</mass>
          <inertia>
            <ixx>0.035516</ixx>
            <ixy>0</ixy>
            <iyy>0.035516</iyy>
            <ixz>0</ixz>
            <iyz>0</iyz>
            <izz>0.0625</izz>
          </inertia>
          <pose>-1 -1.27 -0.25 1.57079 -0 0</pose>
        </inertial>
        <collision name='collision'>
          <pose>-1 -1.27 -0.25 1.57079 -0 0</pose>
          <geometry>
            <cylinder>
              <radius>0.25</radius>
              <length>0.16</length>
            </cylinder>
          </geometry>
          <surface>
            <friction>
              <ode>
                <mu>0.3</mu>
                <mu2>0.3</mu2>
              </ode>
              <torsional>
                <ode/>
              </torsional>
            </friction>
            <contact>
              <ode>
                <max_vel>0.1</max_vel>
                <min_depth>0.001</min_depth>
              </ode>
            </contact>
            <bounce/>
          </surface>
          <max_contacts>10</max_contacts>
        </collision>
        <visual name='visual'>
          <geometry>
            <mesh>
              <uri>model://cessna/meshes/cessna_rear_right_wheel.dae</uri>
            </mesh>
          </geometry>
        </visual>
        <self_collide>0</self_collide>
        <enable_wind>0</enable_wind>
        <kinematic>0</kinematic>
      </link>
      <joint name='left_flap_joint' type='revolute'>
        <parent>body</parent>
        <child>left_flap</child>
        <pose>-1.6 1.55 1.43 0.02 -0 0</pose>
        <axis>
          <xyz>0 1 0</xyz>
          <limit>
            <lower>-0.53</lower>
            <upper>0.53</upper>
            <effort>-1</effort>
            <velocity>-1</velocity>
          </limit>
          <dynamics>
            <damping>1</damping>
            <spring_reference>0</spring_reference>
            <spring_stiffness>0</spring_stiffness>
          </dynamics>
        </axis>
        <physics>
          <ode>
            <implicit_spring_damper>1</implicit_spring_damper>
            <limit>
              <cfm>0</cfm>
              <erp>0.2</erp>
            </limit>
          </ode>
        </physics>
      </joint>
      <joint name='left_aileron_joint' type='revolute'>
        <parent>body</parent>
        <child>left_aileron</child>
        <pose>-1.45 3.7 1.5 0.05 -0 -0.12</pose>
        <axis>
          <xyz>0 1 0</xyz>
          <limit>
            <lower>-0.53</lower>
            <upper>0.53</upper>
            <effort>-1</effort>
            <velocity>-1</velocity>
          </limit>
          <dynamics>
            <damping>1</damping>
            <spring_reference>0</spring_reference>
            <spring_stiffness>0</spring_stiffness>
          </dynamics>
        </axis>
        <physics>
          <ode>
            <implicit_spring_damper>1</implicit_spring_damper>
            <limit>
              <cfm>0</cfm>
              <erp>0.2</erp>
            </limit>
          </ode>
        </physics>
      </joint>
      <joint name='right_flap_joint' type='revolute'>
        <parent>body</parent>
        <child>right_flap</child>
        <pose>-1.6 -1.55 1.43 -0.02 0 0</pose>
        <axis>
          <xyz>0 1 0</xyz>
          <limit>
            <lower>-0.53</lower>
            <upper>0.53</upper>
            <effort>-1</effort>
            <velocity>-1</velocity>
          </limit>
          <dynamics>
            <damping>1</damping>
            <spring_reference>0</spring_reference>
            <spring_stiffness>0</spring_stiffness>
          </dynamics>
        </axis>
        <physics>
          <ode>
            <implicit_spring_damper>1</implicit_spring_damper>
            <limit>
              <cfm>0</cfm>
              <erp>0.2</erp>
            </limit>
          </ode>
        </physics>
      </joint>
      <joint name='right_aileron_joint' type='revolute'>
        <parent>body</parent>
        <child>right_aileron</child>
        <pose>-1.45 -3.7 1.5 -0.05 -0 0.12</pose>
        <axis>
          <xyz>0 1 0</xyz>
          <limit>
            <lower>-0.53</lower>
            <upper>0.53</upper>
            <effort>-1</effort>
            <velocity>-1</velocity>
          </limit>
          <dynamics>
            <damping>1</damping>
            <spring_reference>0</spring_reference>
            <spring_stiffness>0</spring_stiffness>
          </dynamics>
        </axis>
        <physics>
          <ode>
            <implicit_spring_damper>1</implicit_spring_damper>
            <limit>
              <cfm>0</cfm>
              <erp>0.2</erp>
            </limit>
          </ode>
        </physics>
      </joint>
      <joint name='elevators_joint' type='revolute'>
        <parent>body</parent>
        <child>elevators</child>
        <pose>-5.55 0 0.57 0 -0 0</pose>
        <axis>
          <xyz>0 1 0</xyz>
          <limit>
            <lower>-0.53</lower>
            <upper>0.53</upper>
            <effort>-1</effort>
            <velocity>-1</velocity>
          </limit>
          <dynamics>
            <damping>1</damping>
            <spring_reference>0</spring_reference>
            <spring_stiffness>0</spring_stiffness>
          </dynamics>
        </axis>
        <physics>
          <ode>
            <implicit_spring_damper>1</implicit_spring_damper>
            <limit>
              <cfm>0</cfm>
              <erp>0.2</erp>
            </limit>
          </ode>
        </physics>
      </joint>
      <joint name='rudder_joint' type='revolute'>
        <parent>body</parent>
        <child>rudder</child>
        <pose>-5.9 0 1.3 0 -0.35 0</pose>
        <axis>
          <xyz>0 0 1</xyz>
          <limit>
            <lower>-0.53</lower>
            <upper>0.53</upper>
            <effort>-1</effort>
            <velocity>-1</velocity>
          </limit>
          <dynamics>
            <damping>1</damping>
            <spring_reference>0</spring_reference>
            <spring_stiffness>0</spring_stiffness>
          </dynamics>
        </axis>
        <physics>
          <ode>
            <implicit_spring_damper>1</implicit_spring_damper>
            <limit>
              <cfm>0</cfm>
              <erp>0.2</erp>
            </limit>
          </ode>
        </physics>
      </joint>
      <joint name='propeller_joint' type='revolute'>
        <parent>body</parent>
        <child>propeller</child>
        <axis>
          <xyz>1 0 0</xyz>
          <limit>
            <lower>-1e+12</lower>
            <upper>1e+12</upper>
            <effort>-1</effort>
            <velocity>-1</velocity>
          </limit>
          <dynamics>
            <damping>0.001</damping>
            <spring_reference>0</spring_reference>
            <spring_stiffness>0</spring_stiffness>
          </dynamics>
        </axis>
        <physics>
          <ode>
            <implicit_spring_damper>1</implicit_spring_damper>
            <limit>
              <cfm>0</cfm>
              <erp>0.2</erp>
            </limit>
          </ode>
        </physics>
      </joint>
      <joint name='front_wheel_joint' type='revolute'>
        <parent>body</parent>
        <child>front_wheel</child>
        <pose>0.712 0 -0.313 0 -0 0</pose>
        <axis>
          <xyz>0 1 0</xyz>
          <limit>
            <lower>-1e+12</lower>
            <upper>1e+12</upper>
            <effort>-1</effort>
            <velocity>-1</velocity>
          </limit>
          <dynamics>
            <damping>0.01</damping>
            <spring_reference>0</spring_reference>
            <spring_stiffness>0</spring_stiffness>
          </dynamics>
        </axis>
        <physics>
          <ode>
            <implicit_spring_damper>1</implicit_spring_damper>
            <limit>
              <cfm>0</cfm>
              <erp>0.2</erp>
            </limit>
          </ode>
        </physics>
      </joint>
      <joint name='rear_left_wheel_joint' type='revolute'>
        <parent>body</parent>
        <child>rear_left_wheel</child>
        <pose>-1 -1.27 -0.25 0 -0 0</pose>
        <axis>
          <xyz>0 1 0</xyz>
          <limit>
            <lower>-1e+12</lower>
            <upper>1e+12</upper>
            <effort>-1</effort>
            <velocity>-1</velocity>
          </limit>
          <dynamics>
            <damping>0.01</damping>
            <spring_reference>0</spring_reference>
            <spring_stiffness>0</spring_stiffness>
          </dynamics>
        </axis>
        <physics>
          <ode>
            <implicit_spring_damper>1</implicit_spring_damper>
            <limit>
              <cfm>0</cfm>
              <erp>0.2</erp>
            </limit>
          </ode>
        </physics>
      </joint>
      <joint name='rear_right_wheel_joint' type='revolute'>
        <parent>body</parent>
        <child>rear_right_wheel</child>
        <pose>-1 1.27 -0.25 0 -0 0</pose>
        <axis>
          <xyz>0 1 0</xyz>
          <limit>
            <lower>-1e+12</lower>
            <upper>1e+12</upper>
            <effort>-1</effort>
            <velocity>-1</velocity>
          </limit>
          <dynamics>
            <damping>0.01</damping>
            <spring_reference>0</spring_reference>
            <spring_stiffness>0</spring_stiffness>
          </dynamics>
        </axis>
        <physics>
          <ode>
            <implicit_spring_damper>1</implicit_spring_damper>
            <limit>
              <cfm>0</cfm>
              <erp>0.2</erp>
            </limit>
          </ode>
        </physics>
      </joint>
    </model>
  </world>
</sdf>
